Workbook

Sheet Data_Wisata
A1: Tempat Wisata | B1: Rating | C1: Open Time | D1: Closed Time | E1: Min Time (in Minutes) | F1: Biaya | G1: Koordinat x | H1: Koordinat y
A2: Stasiun Solo Balapan (Depart) | B2: 4.4 | C2: 0.16666667 | D2: 0.875 | E2: 15 | F2: 4000 | G2: -7.5570144 | H2: 110.82138
A3: Loji Gandrung | B3: 4.7 | C3: 0.33333333 | D3: 0.66666667 | E3: 30 | F3: 5000 | G3: -7.566982 | H3: 110.80952
A4: Museum Keris Nusantara | B4: 4.7 | C4: 0.33333333 | D4: 0.66666667 | E4: 60 | F4: 10000 | G4: -7.5690197 | H4: 110.81096
A5: Wayang Orang Sriwedari | B5: 4.6 | C5: 0.79166667 | D5: 0.95833333 | E5: 60 | F5: 10000 | G5: -7.5693825 | H5: 110.81251
A6: Museum Batik Danar Hadi | B6: 4.7 | C6: 0.375 | D6: 0.70833333 | E6: 30 | F6: 35000 | G6: -7.5687534 | H6: 110.81634
A7: Pura Mangkunegaran | B7: 4.7 | C7: 0.375 | D7: 0.60416667 | E7: 90 | F7: 30000 | G7: -7.5667625 | H7: 110.82307
A8: Kampung Batik Kauman | B8: 4.7 | C8: 0.375 | D8: 0.75 | E8: 60 | F8: 20000 | G8: -7.5733853 | H8: 110.82631
A9: Pasar Gedhe | B9: 4.6 | C9: 0 | D9: 0.95833333 | E9: 45 | F9: 30000 | G9: -7.5693341 | H9: 110.83162
A10: Lokananta | B10: 4.8 | C10: 0.41666667 | D10: 0.95833333 | E10: 60 | F10: 50000 | G10: -7.5577059 | H10: 110.79576
A11: Masjid Raya Sheikh Zayed | B11: 4.7 | C11: 0.60416667 | D11: 0.875 | E11: 40 | F11: 5000 | G11: -7.5546911 | H11: 110.82678
A12: Taman Safari Solo | B12: 4.1 | C12: 0.35416667 | D12: 0.6875 | E12: 90 | F12: 55000 | G12: -7.5646569 | H12: 110.8586
A13: Pasar Triwindu | B13: 4.6 | C13: 0.375 | D13: 0.66666667 | E13: 30 | F13: 5000 | G13: -7.5691223 | H13: 110.8226
... A15: Stasiun Solo Balapan (Return) | B15: 4.4 | C15: 0.16666667 | D15: 0.875 | E15: 15 | F15: 4000 | G15: -7.5570144 | H15: 110.82138

Sheet Informasi Halte
A1: Nama Halte | B1: Koridor Utama | C1: Koridor
A2: =F_ab!A2 -> Stasiun Solo Balapan A | B2: K2SB | C2: K2SB
A3: =F_ab!A3 -> Stasiun Solo Balapan B | B3: K2SB | C3: K2SB
A4: =F_ab!#REF! -> #REF! | B4: K2SB | C4: K2SB
A5: =F_ab!A4 -> Halte Viaduk Selatan | B5: K4SB | C5: K4SB
A6: =F_ab!A5 -> Halte Viaduk Gilingan | B6: K4SB | C6: K4SB
A7: =F_ab!#REF! -> #REF! | B7: FD9 | C7: FD9
A8: =F_ab!#REF! -> #REF! | B8: K4SB | C8: K4SB, K3SB
A9: =F_ab!A6 -> Halte Jurug 1 | B9: K4SB | C9: K4SB
A10: =F_ab!#REF! -> #REF! | B10: K1S | C10: K2SB, K1S
A11: =F_ab!#REF! -> #REF! | B11: K1S | C11: K1S
A12: =F_ab!A7 -> Halte Jurug 2 | B12: K4SB | C12: K2SB, K4SB
A13: =F_ab!#REF! -> #REF! | B13: K2SB | C13: K2SB, K1S
A14: =F_ab!#REF! -> #REF! | B14: FD7 | C14: FD10S, K3SB, FD7, K1S
A15: =F_ab!#REF! -> #REF! | B15: FD12 | C15: FD10S, FD12, FD7
A16: =F_ab!#REF! -> #REF! | B16: K3SB | C16: FD10S, K3SB
A17: =F_ab!#REF! -> #REF! | B17: K1S | C17: FD7, K1S
A18: =F_ab!#REF! -> #REF! | B18: FD7 | C18: FD10S, FD7
A19: =F_ab!#REF! -> #REF! | B19: FD7 | C19: FD10S, K3SB, K3M#, K1M#, FD7, K1S
A20: =F_ab!#REF! -> #REF! | B20: FD10S | C20: FD10S, K3SB, FD7, K1S
A21: =F_ab!A8 -> Pasar Gede A | B21: FD10S | C21: FD10S, K3SB, FD7, K1S
A22: =F_ab!A9 -> Pasar Gede B | B22: K3SB | C22: FD10S, K3SB, FD7, K1S
A23: =F_ab!A10 -> Halte Pasar Klewer | B23: FD12 | C23: FD12, FD7
A24: =F_ab!A11 -> Gladag A | B24: K1S | C24: K1S
A25: =F_ab!A12 -> Gladag B | B25: K3SB | C25: K3SB, K1S
A26: =F_ab!#REF! -> #REF! | B26: FD10S | C26: FD10S, FD12, FD7
A27: =F_ab!#REF! -> #REF! | B27: FD9 | C27: FD9
A28: =F_ab!A13 -> Pasar Pon A | B28: K1S | C28: K1S
A29: =F_ab!A14 -> Pasar Pon B | B29: K1S | C29: K5SB, K1S
A30: =F_ab!#REF! -> #REF! | B30: FD10S | C30: FD10S
A31: =F_ab!A15 -> Ngapeman A | B31: K1S | C31: K5SB, FD8S, K1S
A32: =F_ab!A16 -> Ngapeman B | B32: K1S | C32: K5SB, FD8S, K1S
A33: =F_ab!#REF! -> #REF! | B33: FD8S | C33: K5SB, FD8S, K1S
A34: =F_ab!#REF! -> #REF! | B34: K5SB | C34: K5SB, FD8S, FD12, K1S
A35: =F_ab!A17 -> Kelurahan Sri Wedari | B35: FD12 | C35: FD12
A36: =F_ab!A18 -> Halte Museum Keris A | B36: FD8S | C36: FD8S
A37: =F_ab!A19 -> Halte Museum Keris B | B37: FD8S | C37: FD8S
A38: =F_ab!A20 -> Sriwedari 1 A | B38: K5SB | C38: K5SB, FD8S, FD12, K1S
A39: =F_ab!A21 -> Sriwedari 1 B | B39: K5SB | C39: K5SB, FD8S, K1S
A40: =F_ab!A22 -> 0
...

Sheet F_ab
B1: Stasiun Solo Balapan A | C1: Stasiun Solo Balapan B | D1: Halte Viaduk Selatan | E1: Halte Viaduk Gilingan | F1: Halte Jurug 1 | G1: Halte Jurug 2 | H1: Pasar Gede A | I1: Pasar Gede B | J1: Halte Pasar Klewer | K1: Gladag A | L1: Gladag B | M1: Pasar Pon A | N1: Pasar Pon B | O1: Ngapeman A | P1: Ngapeman B | Q1: Kelurahan Sri Wedari | R1: Halte Museum Keris A | S1: Halte Museum Keris B | T1: Sriwedari 1 A | U1: Sriwedari 1 B
A2: Stasiun Solo Balapan A | B2: 0 | C2: 0 | D2: 0 | E2: 0 | F2: 1 | G2: 0 | H2: 0 | I2: 0 | J2: 0 | K2: 0 | L2: 0 | M2: 0 | N2: 0 | O2: 0 | P2: 0 | Q2: 0 | R2: 0 | S2: 0 | T2: 0 | U2: 0
A3: Stasiun Solo Balapan B | B3: 0 | C3: 0 | D3: 0 | E3: 0 | F3: 0 | G3: 0 | H3: 0 | I3: 0 | J3: 0 | K3: 0 | L3: 0 | M3: 0 | N3: 0 | O3: 0 | P3: 0 | Q3: 0 | R3: 0 | S3: 0 | T3: 0 | U3: 0
A4: Halte Viaduk Selatan | B4: 0 | C4: 0 | D4: 0 | E4: 0 | F4: 0 | G4: 0 | H4: 0 | I4: 0 | J4: 0 | K4: 0 | L4: 0 | M4: 0 | N4: 0 | O4: 0 | P4: 0 | Q4: 0 | R4: 0 | S4: 0 | T4: 0 | U4: 0
A5: Halte Viaduk Gilingan | B5: 0 | C5: 0 | D5: 0 | E5: 0 | F5: 1 | G5: 0 | H5: 0 | I5: 0 | J5: 0 | K5: 0 | L5: 0 | M5: 0 | N5: 0 | O5: 0 | P5: 0 | Q5: 0 | R5: 0 | S5: 0 | T5: 0 | U5: 0
A6: Halte Jurug 1 | B6: 0 | C6: 0 | D6: 0 | E6: 0 | F6: 0 | G6: 0 | H6: 0 | I6: 0 | J6: 0 | K6: 0 | L6: 0 | M6: 0 | N6: 0 | O6: 0 | P6: 0 | Q6: 0 | R6: 0 | S6: 0 | T6: 0 | U6: 0
A7: Halte Jurug 2 | B7: 0 | C7: 1 | D7: 1 | E7: 0 | F7: 0 | G7: 0 | H7: 0 | I7: 1 | J7: 0 | K7: 1 | L7: 0 | M7: 1 | N7: 0 | O7: 0 | P7: 1 | Q7: 0 | R7: 0 | S7: 0 | T7: 0 | U7: 1
A8: Pasar Gede A | B8: 0 | C8: 0 | D8: 0 | E8: 0 | F8: 1 | G8: 0 | H8: 0 | I8: 0 | J8: 0 | K8: 0 | L8: 0 | M8: 0 | N8: 0 | O8: 0 | P8: 0 | Q8: 0 | R8: 0 | S8: 0 | T8: 0 | U8: 0
A9: Pasar Gede B | B9: 0 | C9: 0 | D9: 0 | E9: 0 | F9: 0 | G9: 0 | H9: 0 | I9: 0 | J9: 1 | K9: 0 | L9: 0 | M9: 0 | N9: 0 | O9: 0 | P9: 0 | Q9: 0 | R9: 0 | S9: 0 | T9: 0 | U9: 0
A10: Halte Pasar Klewer | B10: 0 | C10: 0 | D10: 0 | E10: 0 | F10: 0 | G10: 0 | H10: 1 | I10: 0 | J10: 0 | K10: 0 | L10: 0 | M10: 0 | N10: 0 | O10: 0 | P10: 0 | Q10: 1 | R10: 0 | S10: 0 | T10: 0 | U10: 0
A11: Gladag A | B11: 0 | C11: 0 | D11: 0 | E11: 0 | F11: 0 | G11: 0 | H11: 0 | I11: 0 | J11: 0 | K11: 0 | L11: 0 | M11: 1 | N11: 0 | O11: 0 | P11: 1 | Q11: 0 | R11: 0 | S11: 0 | T11: 0 | U11: 0
A12: Gladag B | B12: 0 | C12: 0 | D12: 0 | E12: 0 | F12: 1 | G12: 0 | H12: 1 | I12: 0 | J12: 0 | K12: 0 | L12: 0 | M12: 0 | N12: 0 | O12: 0 | P12: 0 | Q12: 0 | R12: 0 | S12: 0 | T12: 0 | U12: 0
A13: Pasar Pon A | B13: 0 | C13: 0 | D13: 0 | E13: 0 | F13: 0 | G13: 0 | H13: 0 | I13: 0 | J13: 0 | K13: 0 | L13: 0 | M13: 0 | N13: 0 | O13: 0 | P13: 0 | Q13: 0 | R13: 0 | S13: 0 | T13: 0 | U13: 0
... A21: Sriwedari 1 B | B21: 0 | C21: 0 | D21: 0 | E21: 0 | F21: 0 | G21: 0 | H21: 0 | I21: 0 | J21: 0 | K21: 0 | L21: 0 | M21: 0 | N21: 0 | O21: 0 | P21: 0 | Q21: 0 | R21: 1 | S21: 0 | T21: 0 | U21: 0

Sheet theta
B1: Stasiun Solo Balapan A | C1: Stasiun Solo Balapan B | D1: Halte Viaduk Selatan | E1: Halte Viaduk Gilingan | F1: Halte Jurug 1 | G1: Halte Jurug 2 | H1: Pasar Gede A | I1: Pasar Gede B | J1: Halte Pasar Klewer | K1: Gladag A | L1: Gladag B | M1: Pasar Pon A | N1: Pasar Pon B | O1: Ngapeman A | P1: Ngapeman B | Q1: Kelurahan Sri Wedari | R1: Halte Museum Keris A | S1: Halte Museum Keris B | T1: Sriwedari 1 A | U1: Sriwedari 1 B
A2: Stasiun Solo Balapan (Berangkat) | B2: 1 | C2: 1 | D2: 0 | E2: 0 | F2: 0 | G2: 0 | H2: 0 | I2: 0 | J2: 0 | K2: 0 | L2: 0 | M2: 0 | N2: 0 | O2: 0 | P2: 0 | Q2: 0 | R2: 0 | S2: 0 | T2: 0 | U2: 0
A3: Loji Gandrung | B3: 0 | C3: 0 | D3: 0 | E3: 0 | F3: 0 | G3: 0 | H3: 0 | I3: 0 | J3: 0 | K3: 0 | L3: 0 | M3: 0 | N3: 0 | O3: 0 | P3: 0 | Q3: 0 | R3: 0 | S3: 0 | T3: 1 | U3: 1
A4: Museum Keris Nusantara | B4: 0 | C4: 0 | D4: 0 | E4: 0 | F4: 0 | G4: 0 | H4: 0 | I4: 0 | J4: 0 | K4: 0 | L4: 0 | M4: 0 | N4: 0 | O4: 0 | P4: 0 | Q4: 0 | R4: 1 | S4: 1 | T4: 0 | U4: 0
A5: Wayang Orang Sriwedari | B5: 0 | C5: 0 | D5: 0 | E5: 0 | F5: 0 | G5: 0 | H5: 0 | I5: 0 | J5: 0 | K5: 0 | L5: 0 | M5: 0 | N5: 0 | O5: 0 | P5: 0 | Q5: 1 | R5: 0 | S5: 0 | T5: 0 | U5: 0
A6: Museum Batik Danar Hadi | B6: 0 | C6: 0 | D6: 0 | E6: 0 | F6: 0 | G6: 0 | H6: 0 | I6: 0 | J6: 0 | K6: 0 | L6: 0 | M6: 0 | N6: 0 | O6: 1 | P6: 1 | Q6: 0 | R6: 0 | S6: 0 | T6: 0 | U6: 0
A7: Pura Mangkunegaran | B7: 0 | C7: 0 | D7: 0 | E7: 0 | F7: 0 | G7: 0 | H7: 0 | I7: 0 | J7: 0 | K7: 0 | L7: 0 | M7: 0 | N7: 0 | O7: 0 | P7: 0 | Q7: 0 | R7: 0 | S7: 0 | T7: 0 | U7: 0
A8: Kampung Batik Kauman | B8: 0 | C8: 0 | D8: 0 | E8: 0 | F8: 0 | G8: 0 | H8: 0 | I8: 0 | J8: 1 | K8: 1 | L8: 1 | M8: 0 | N8: 0 | O8: 0 | P8: 0 | Q8: 0 | R8: 0 | S8: 0 | T8: 0 | U8: 0
A9: Pasar Gedhe | B9: 0 | C9: 0 | D9: 0 | E9: 0 | F9: 0 | G9: 0 | H9: 1 | I9: 1 | J9: 0 | K9: 0 | L9: 0 | M9: 0 | N9: 0 | O9: 0 | P9: 0 | Q9: 0 | R9: 0 | S9: 0 | T9: 0 | U9: 0
A10: Lokananta | B10: 0 | C10: 0 | D10: 0 | E10: 0 | F10: 0 | G10: 0 | H10: 0 | I10: 0 | J10: 0 | K10: 0 | L10: 0 | M10: 0 | N10: 0 | O10: 0 | P10: 0 | Q10: 0 | R10: 0 | S10: 0 | T10: 0 | U10: 0
A11: Masjid Raya Sheikh Zayed | B11: 0 | C11: 0 | D11: 1 | E11: 1 | F11: 0 | G11: 0 | H11: 0 | I11: 0 | J11: 0 | K11: 0 | L11: 0 | M11: 0 | N11: 0 | O11: 0 | P11: 0 | Q11: 0 | R11: 0 | S11: 0 | T11: 0 | U11: 0
A12: Taman Safari Solo | B12: 0 | C12: 0 | D12: 0 | E12: 0 | F12: 1 | G12: 1 | H12: 0 | I12: 0 | J12: 0 | K12: 0 | L12: 0 | M12: 0 | N12: 0 | O12: 0 | P12: 0 | Q12: 0 | R12: 0 | S12: 0 | T12: 0 | U12: 0
A13: Pasar Triwindu | B13: 0 | C13: 0 | D13: 0 | E13: 0 | F13: 0 | G13: 0 | H13: 0 | I13: 0 | J13: 0 | K13: 0 | L13: 0 | M13: 1 | N13: 1 | O13: 0 | P13: 0 | Q13: 0 | R13: 0 | S13: 0 | T13: 0 | U13: 0
... A15: Stasiun Solo Balapan (Pulang) | B15: 1 | C15: 1 | D15: 0 | E15: 0 | F15: 0 | G15: 0 | H15: 0 | I15: 0 | J15: 0 | K15: 0 | L15: 0 | M15: 0 | N15: 0 | O15: 0 | P15: 0 | Q15: 0 | R15: 0 | S15: 0 | T15: 0 | U15: 0

Sheet distance_d
A1: KM | B1: Stasiun Solo Balapan (Berangkat) | C1: Loji Gandrung | D1: Museum Keris Nusantara | E1: Wayang Orang Sriwedari | F1: Museum Batik Danar Hadi | G1: Pura Mangkunegaran | H1: Kampung Batik Kauman | I1: Pasar Gedhe | J1: Lokananta | K1: Masjid Raya Sheikh Zayed | L1: Taman Safari Solo | M1: Pasar Triwindu | N1: Koridor Gatsu | O1: Stasiun Solo Balapan (Pulang)
A2: Stasiun Solo Balapan (Berangkat) | B2: 0 | C2: 3 | D2: 2.7 | E2: 2.5 | F2: 2.1 | G2: 1.5 | H2: 2.7 | I2: 2.5 | J2: 3.7 | K2: 1.2 | L2: 4.7 | M2: 2 | N2: 2.5 | O2: 0
A3: Loji Gandrung | B3: 2.3 | C3: 0 | D3: 0.4 | E3: 0.8 | F3: 0.8 | G3: 1.6 | H3: 2.3 | I3: 2.8 | J3: 3.6 | K3: 3.5 | L3: 7.1 | M3: 1.5 | N3: 2.6 | O3: 2.3
A4: Museum Keris Nusantara | B4: 2.4 | C4: 0.75 | D4: 0 | E4: 0.4 | F4: 0.9 | G4: 1.7 | H4: 2.6 | I4: 2.9 | J4: 3.4 | K4: 3.6 | L4: 7.2 | M4: 1.6 | N4: 1.6 | O4: 2.4
A5: Wayang Orang Sriwedari | B5: 2.1 | C5: 1.4 | D5: 0.4 | E5: 0 | F5: 0.65 | G5: 1.4 | H5: 2.2 | I5: 2.6 | J5: 3.6 | K5: 3.4 | L5: 7 | M5: 1.5 | N5: 1.4 | O5: 2.1
A6: Museum Batik Danar Hadi | B6: 1.5 | C6: 2.1 | D6: 1.2 | E6: 0.95 | F6: 0 | G6: 0.85 | H6: 1.5 | I6: 2.1 | J6: 4.4 | K6: 2.8 | L6: 6.4 | M6: 0.8 | N6: 0.85 | O6: 1.5
A7: Pura Mangkunegaran | B7: 1.2 | C7: 2 | D7: 2 | E7: 1.6 | F7: 1.5 | G7: 0 | H7: 1.1 | I7: 1 | J7: 3.9 | K7: 1.9 | L7: 5 | M7: 0.19 | N7: 0.45 | O7: 1.2
A8: Kampung Batik Kauman | B8: 2.7 | C8: 3.5 | D8: 2.5 | E8: 2.3 | F8: 2.3 | G8: 1.1 | H8: 0 | I8: 1 | J8: 5.7 | K8: 2.8 | L8: 5.3 | M8: 0.9 | N8: 0.65 | O8: 2.7
A9: Pasar Gedhe | B9: 2.3 | C9: 3.5 | D9: 3.5 | E9: 3.2 | F9: 3.1 | G9: 1.5 | H9: 1.7 | I9: 0 | J9: 5.2 | K9: 2 | L9: 4 | M9: 1.7 | N9: 2.4 | O9: 2.3
A10: Lokananta | B10: 4.5 | C10: 2.8 | D10: 3.3 | E10: 3.6 | F10: 3.6 | G10: 4.4 | H10: 5.1 | I10: 5.6 | J10: 0 | K10: 4.5 | L10: 8.5 | M10: 4.4 | N10: 4.7 | O10: 4.5
A11: Masjid Raya Sheikh Zayed | B11: 1.5 | C11: 4.1 | D11: 3.9 | E11: 3.7 | F11: 3.3 | G11: 1.8 | H11: 2.6 | I11: 2.5 | J11: 4.1 | K11: 0 | L11: 4.5 | M11: 2.3 | N11: 3.2 | O11: 1.5
A12: Taman Safari Solo | B12: 4.9 | C12: 7.5 | D12: 7.5 | E12: 7.3 | F12: 6.7 | G12: 5.2 | H12: 5.7 | I12: 4.2 | J12: 8.1 | K12: 4.3 | L12: 0 | M12: 5.7 | N12: 6.4 | O12: 4.9
A13: Pasar Triwindu | B13: 2 | C13: 2.1 | D13: 2.1 | E13: 1.8 | F13: 1.7 | G13: 0.19 | H13: 1 | I13: 1.5 | J13: 4.4 | K13: 2.4 | L13: 5.8 | M13: 0 | N13: 0.3 | O13: 2
A14: Koridor Gatsu | B14: 2 | C14: 2.5 | D14: 1.8 | E14: 1.3 | F14: 1.4 | G14: 0.45 | H14: 1 | I14: 1.6 | J14: 4.7 | K14: 2.7 | L14: 5.8 | M14: 0.3 | N14: 0 | O14: 2
A15: Stasiun Solo Balapan (Pulang) | B15: 0 | C15: 3 | D15: 2.7 | E15: 2.5 | F15: 2.1 | G15: 1.5 | H15: 2.7 | I15: 2.5 | J15: 3.7 | K15: 1.2 | L15: 4.7 | M15: 2 | N15: 2.5 | O15: 0

Sheet time_t
A1: MINUTES | B1: Stasiun Solo Balapan A | C1: Stasiun Solo Balapan B | D1: Halte Viaduk Selatan | E1: Halte Viaduk Gilingan | F1: Halte Jurug 1 | G1: Halte Jurug 2 | H1: Pasar Gede A | I1: Pasar Gede B | J1: Halte Pasar Klewer | K1: Gladag A | L1: Gladag B | M1: Pasar Pon A | N1: Pasar Pon B | O1: Ngapeman A | P1: Ngapeman B | Q1: Kelurahan Sri Wedari | R1: Halte Museum Keris A | S1: Halte Museum Keris B | T1: Sriwedari 1 A | U1: Sriwedari 1 B
A2: Stasiun Solo Balapan A | B2: 0 | C2: 0 | D2: 0 | E2: 0 | F2: 20 | G2: 0 | H2: 0 | I2: 0 | J2: 0 | K2: 0 | L2: 0 | M2: 0 | N2: 0 | O2: 0 | P2: 0 | Q2: 0 | R2: 0 | S2: 0 | T2: 0 | U2: 0
A3: Stasiun Solo Balapan B | B3: 0 | C3: 0 | D3: 0 | E3: 0 | F3: 0 | G3: 0 | H3: 0 | I3: 0 | J3: 0 | K3: 0 | L3: 0 | M3: 0 | N3: 0 | O3: 0 | P3: 0 | Q3: 0 | R3: 0 | S3: 0 | T3: 0 | U3: 0
A4: Halte Viaduk Selatan | B4: 0 | C4: 0 | D4: 0 | E4: 0 | F4: 0 | G4: 0 | H4: 0 | I4: 0 | J4: 0 | K4: 0 | L4: 0 | M4: 0 | N4: 0 | O4: 0 | P4: 0 | Q4: 0 | R4: 0 | S4: 0 | T4: 0 | U4: 0
A5: Halte Viaduk Gilingan | B5: 0 | C5: 0 | D5: 0 | E5: 0 | F5: 20 | G5: 0 | H5: 0 | I5: 0 | J5: 0 | K5: 0 | L5: 0 | M5: 0 | N5: 0 | O5: 0 | P5: 0 | Q5: 0 | R5: 0 | S5: 0 | T5: 0 | U5: 0
A6: Halte Jurug 1 | B6: 0 | C6: 0 | D6: 0 | E6: 0 | F6: 0 | G6: 0 | H6: 0 | I6: 0 | J6: 0 | K6: 0 | L6: 0 | M6: 0 | N6: 0 | O6: 0 | P6: 0 | Q6: 0 | R6: 0 | S6: 0 | T6: 0 | U6: 0
A7: Halte Jurug 2 | B7: 0 | C7: 20 | D7: 21 | E7: 0 | F7: 0 | G7: 0 | H7: 0 | I7: 17 | J7: 0 | K7: 20 | L7: 0 | M7: 22 | N7: 0 | O7: 0 | P7: 25 | Q7: 0 | R7: 0 | S7: 0 | T7: 0 | U7: 27
A8: Pasar Gede A | B8: 0 | C8: 0 | D8: 0 | E8: 0 | F8: 19 | G8: 0 | H8: 0 | I8: 0 | J8: 0 | K8: 0 | L8: 0 | M8: 0 | N8: 0 | O8: 0 | P8: 0 | Q8: 0 | R8: 0 | S8: 0 | T8: 0 | U8: 0
A9: Pasar Gede B | B9: 0 | C9: 0 | D9: 0 | E9: 0 | F9: 0 | G9: 0 | H9: 0 | I9: 0 | J9: 9 | K9: 0 | L9: 0 | M9: 0 | N9: 0 | O9: 0 | P9: 0 | Q9: 0 | R9: 0 | S9: 0 | T9: 0 | U9: 0
A10: Halte Pasar Klewer | B10: 0 | C10: 0 | D10: 0 | E10: 0 | F10: 0 | G10: 0 | H10: 12 | I10: 0 | J10: 0 | K10: 0 | L10: 0 | M10: 0 | N10: 0 | O10: 0 | P10: 0 | Q10: 30 | R10: 0 | S10: 0 | T10: 0 | U10: 0
A11: Gladag A | B11: 0 | C11: 0 | D11: 0 | E11: 0 | F11: 0 | G11: 0 | H11: 0 | I11: 0 | J11: 0 | K11: 0 | L11: 0 | M11: 2 | N11: 0 | O11: 0 | P11: 5 | Q11: 0 | R11: 0 | S11: 0 | T11: 0 | U11: 0
A12: Gladag B | B12: 0 | C12: 0 | D12: 0 | E12: 0 | F12: 22 | G12: 0 | H12: 6 | I12: 0 | J12: 0 | K12: 0 | L12: 0 | M12: 0 | N12: 0 | O12: 0 | P12: 0 | Q12: 0 | R12: 0 | S12: 0 | T12: 0 | U12: 0
A13: Pasar Pon A | B13: 0 | C13: 0 | D13: 0 | E13: 0 | F13: 0 | G13: 0 | H13: 0 | I13: 0 | J13: 0 | K13: 0 | L13: 0 | M13: 0 | N13: 0 | O13: 0 | P13: 0 | Q13: 0 | R13: 0 | S13: 0 | T13: 0 | U13: 0
... A21: Sriwedari 1 B | B21: 0 | C21: 0 | D21: 0 | E21: 0 | F21: 0 | G21: 0 | H21: 0 | I21: 0 | J21: 0 | K21: 0 | L21: 0 | M21: 0 | N21: 0 | O21: 0 | P21: 0 | Q21: 0 | R21: 2 | S21: 0 | T21: 0 | U21: 0
